2025-08-04 12:15:42,928 INFO    MainThread:12916 [wandb_setup.py:_flush():80] Current SDK version is 0.21.0
2025-08-04 12:15:42,928 INFO    MainThread:12916 [wandb_setup.py:_flush():80] Configure stats pid to 12916
2025-08-04 12:15:42,928 INFO    MainThread:12916 [wandb_setup.py:_flush():80] Loading settings from C:\Users\visha\.config\wandb\settings
2025-08-04 12:15:42,928 INFO    MainThread:12916 [wandb_setup.py:_flush():80] Loading settings from C:\Users\visha\Downloads\ML_ASSIGNMENT_AYNA\wandb\settings
2025-08-04 12:15:42,928 INFO    MainThread:12916 [wandb_setup.py:_flush():80] Loading settings from environment variables
2025-08-04 12:15:42,928 INFO    MainThread:12916 [wandb_init.py:setup_run_log_directory():703] Logging user logs to C:\Users\visha\Downloads\ML_ASSIGNMENT_AYNA\wandb\run-20250804_121542-a3fmt7ch\logs\debug.log
2025-08-04 12:15:42,930 INFO    MainThread:12916 [wandb_init.py:setup_run_log_directory():704] Logging internal logs to C:\Users\visha\Downloads\ML_ASSIGNMENT_AYNA\wandb\run-20250804_121542-a3fmt7ch\logs\debug-internal.log
2025-08-04 12:15:42,930 INFO    MainThread:12916 [wandb_init.py:init():830] calling init triggers
2025-08-04 12:15:42,930 INFO    MainThread:12916 [wandb_init.py:init():835] wandb.init called with sweep_config: {}
config: {'_wandb': {}}
2025-08-04 12:15:42,930 INFO    MainThread:12916 [wandb_init.py:init():871] starting backend
2025-08-04 12:15:43,145 INFO    MainThread:12916 [wandb_init.py:init():874] sending inform_init request
2025-08-04 12:15:43,199 INFO    MainThread:12916 [wandb_init.py:init():882] backend started and connected
2025-08-04 12:15:43,199 INFO    MainThread:12916 [wandb_init.py:init():953] updated telemetry
2025-08-04 12:15:43,203 INFO    MainThread:12916 [wandb_init.py:init():977] communicating run to backend with 90.0 second timeout
2025-08-04 12:15:44,267 INFO    MainThread:12916 [wandb_init.py:init():1029] starting run threads in backend
2025-08-04 12:15:44,330 INFO    MainThread:12916 [wandb_run.py:_console_start():2458] atexit reg
2025-08-04 12:15:44,330 INFO    MainThread:12916 [wandb_run.py:_redirect():2306] redirect: wrap_raw
2025-08-04 12:15:44,330 INFO    MainThread:12916 [wandb_run.py:_redirect():2375] Wrapping output streams.
2025-08-04 12:15:44,330 INFO    MainThread:12916 [wandb_run.py:_redirect():2398] Redirects installed.
2025-08-04 12:15:44,334 INFO    MainThread:12916 [wandb_init.py:init():1075] run started, returning control to user process
2025-08-04 14:56:53,588 INFO    MainThread:12916 [retry.py:__call__():173] Retry attempt failed:
Traceback (most recent call last):
  File "C:\Users\visha\AppData\Roaming\Python\Python313\site-packages\urllib3\connection.py", line 198, in _new_conn
    sock = connection.create_connection(
        (self._dns_host, self.port),
    ...<2 lines>...
        socket_options=self.socket_options,
    )
  File "C:\Users\visha\AppData\Roaming\Python\Python313\site-packages\urllib3\util\connection.py", line 60, in create_connection
    for res in socket.getaddrinfo(host, port, family, socket.SOCK_STREAM):
               ~~~~~~~~~~~~~~~~~~^^^^^^^^^^^^^^^^^^^^^^^^^^^^^^^^^^^^^^^^
  File "C:\Python313\Lib\socket.py", line 977, in getaddrinfo
    for res in _socket.getaddrinfo(host, port, family, type, proto, flags):
               ~~~~~~~~~~~~~~~~~~~^^^^^^^^^^^^^^^^^^^^^^^^^^^^^^^^^^^^^^^^
socket.gaierror: [Errno 11001] getaddrinfo failed

The above exception was the direct cause of the following exception:

Traceback (most recent call last):
  File "C:\Users\visha\AppData\Roaming\Python\Python313\site-packages\urllib3\connectionpool.py", line 787, in urlopen
    response = self._make_request(
        conn,
    ...<10 lines>...
        **response_kw,
    )
  File "C:\Users\visha\AppData\Roaming\Python\Python313\site-packages\urllib3\connectionpool.py", line 488, in _make_request
    raise new_e
  File "C:\Users\visha\AppData\Roaming\Python\Python313\site-packages\urllib3\connectionpool.py", line 464, in _make_request
    self._validate_conn(conn)
    ~~~~~~~~~~~~~~~~~~~^^^^^^
  File "C:\Users\visha\AppData\Roaming\Python\Python313\site-packages\urllib3\connectionpool.py", line 1093, in _validate_conn
    conn.connect()
    ~~~~~~~~~~~~^^
  File "C:\Users\visha\AppData\Roaming\Python\Python313\site-packages\urllib3\connection.py", line 753, in connect
    self.sock = sock = self._new_conn()
                       ~~~~~~~~~~~~~~^^
  File "C:\Users\visha\AppData\Roaming\Python\Python313\site-packages\urllib3\connection.py", line 205, in _new_conn
    raise NameResolutionError(self.host, self, e) from e
urllib3.exceptions.NameResolutionError: <urllib3.connection.HTTPSConnection object at 0x000001A96A2B6990>: Failed to resolve 'api.wandb.ai' ([Errno 11001] getaddrinfo failed)

The above exception was the direct cause of the following exception:

Traceback (most recent call last):
  File "C:\Users\visha\AppData\Roaming\Python\Python313\site-packages\requests\adapters.py", line 667, in send
    resp = conn.urlopen(
        method=request.method,
    ...<9 lines>...
        chunked=chunked,
    )
  File "C:\Users\visha\AppData\Roaming\Python\Python313\site-packages\urllib3\connectionpool.py", line 841, in urlopen
    retries = retries.increment(
        method, url, error=new_e, _pool=self, _stacktrace=sys.exc_info()[2]
    )
  File "C:\Users\visha\AppData\Roaming\Python\Python313\site-packages\urllib3\util\retry.py", line 519, in increment
    raise MaxRetryError(_pool, url, reason) from reason  # type: ignore[arg-type]
    ^^^^^^^^^^^^^^^^^^^^^^^^^^^^^^^^^^^^^^^^^^^^^^^^^^^
urllib3.exceptions.MaxRetryError: HTTPSConnectionPool(host='api.wandb.ai', port=443): Max retries exceeded with url: /graphql (Caused by NameResolutionError("<urllib3.connection.HTTPSConnection object at 0x000001A96A2B6990>: Failed to resolve 'api.wandb.ai' ([Errno 11001] getaddrinfo failed)"))

During handling of the above exception, another exception occurred:

Traceback (most recent call last):
  File "C:\Users\visha\AppData\Roaming\Python\Python313\site-packages\wandb\sdk\lib\retry.py", line 134, in __call__
    result = self._call_fn(*args, **kwargs)
  File "C:\Users\visha\AppData\Roaming\Python\Python313\site-packages\wandb\apis\public\api.py", line 110, in execute
    return self._client.execute(*args, **kwargs)
           ~~~~~~~~~~~~~~~~~~~~^^^^^^^^^^^^^^^^^
  File "C:\Users\visha\AppData\Roaming\Python\Python313\site-packages\wandb\vendor\gql-0.2.0\wandb_gql\client.py", line 52, in execute
    result = self._get_result(document, *args, **kwargs)
  File "C:\Users\visha\AppData\Roaming\Python\Python313\site-packages\wandb\vendor\gql-0.2.0\wandb_gql\client.py", line 60, in _get_result
    return self.transport.execute(document, *args, **kwargs)
           ~~~~~~~~~~~~~~~~~~~~~~^^^^^^^^^^^^^^^^^^^^^^^^^^^
  File "C:\Users\visha\AppData\Roaming\Python\Python313\site-packages\wandb\sdk\lib\gql_request.py", line 58, in execute
    request = self.session.post(self.url, **post_args)
  File "C:\Users\visha\AppData\Roaming\Python\Python313\site-packages\requests\sessions.py", line 637, in post
    return self.request("POST", url, data=data, json=json, **kwargs)
           ~~~~~~~~~~~~^^^^^^^^^^^^^^^^^^^^^^^^^^^^^^^^^^^^^^^^^^^^^
  File "C:\Users\visha\AppData\Roaming\Python\Python313\site-packages\requests\sessions.py", line 589, in request
    resp = self.send(prep, **send_kwargs)
  File "C:\Users\visha\AppData\Roaming\Python\Python313\site-packages\requests\sessions.py", line 703, in send
    r = adapter.send(request, **kwargs)
  File "C:\Users\visha\AppData\Roaming\Python\Python313\site-packages\requests\adapters.py", line 700, in send
    raise ConnectionError(e, request=request)
requests.exceptions.ConnectionError: HTTPSConnectionPool(host='api.wandb.ai', port=443): Max retries exceeded with url: /graphql (Caused by NameResolutionError("<urllib3.connection.HTTPSConnection object at 0x000001A96A2B6990>: Failed to resolve 'api.wandb.ai' ([Errno 11001] getaddrinfo failed)"))
2025-08-04 16:39:19,565 INFO    MsgRouterThr:12916 [mailbox.py:close():129] [no run ID] Closing mailbox, abandoning 1 handles.
